[2021-06-19 20:30:22,728] {taskinstance.py:876} INFO - Dependencies all met for <TaskInstance: dag_finance.import_stock_data 2021-06-19T20:30:14.978076+00:00 [queued]>
[2021-06-19 20:30:22,792] {taskinstance.py:876} INFO - Dependencies all met for <TaskInstance: dag_finance.import_stock_data 2021-06-19T20:30:14.978076+00:00 [queued]>
[2021-06-19 20:30:22,794] {taskinstance.py:1067} INFO - 
--------------------------------------------------------------------------------
[2021-06-19 20:30:22,796] {taskinstance.py:1068} INFO - Starting attempt 1 of 1
[2021-06-19 20:30:22,797] {taskinstance.py:1069} INFO - 
--------------------------------------------------------------------------------
[2021-06-19 20:30:22,830] {taskinstance.py:1087} INFO - Executing <Task(PythonOperator): import_stock_data> on 2021-06-19T20:30:14.978076+00:00
[2021-06-19 20:30:22,860] {standard_task_runner.py:52} INFO - Started process 9651 to run task
[2021-06-19 20:30:22,864] {standard_task_runner.py:76} INFO - Running: ['***', 'tasks', 'run', 'dag_finance', 'import_stock_data', '2021-06-19T20:30:14.978076+00:00', '--job-id', '6', '--pool', 'default_pool', '--raw', '--subdir', 'DAGS_FOLDER/finance_dag.py', '--cfg-path', '/tmp/tmpze384_zv', '--error-file', '/tmp/tmp9d1fc_k1']
[2021-06-19 20:30:22,865] {standard_task_runner.py:77} INFO - Job 6: Subtask import_stock_data
[2021-06-19 20:30:23,052] {logging_mixin.py:104} INFO - Running <TaskInstance: dag_finance.import_stock_data 2021-06-19T20:30:14.978076+00:00 [running]> on host 332a8aeda0e3
[2021-06-19 20:30:23,215] {taskinstance.py:1282} INFO - Exporting the following env vars:
AIRFLOW_CTX_DAG_OWNER=***
AIRFLOW_CTX_DAG_ID=dag_finance
AIRFLOW_CTX_TASK_ID=import_stock_data
AIRFLOW_CTX_EXECUTION_DATE=2021-06-19T20:30:14.978076+00:00
AIRFLOW_CTX_DAG_RUN_ID=manual__2021-06-19T20:30:14.978076+00:00
[2021-06-19 20:30:23,219] {taskinstance.py:1481} ERROR - Task failed with exception
Traceback (most recent call last):
  File "/home/airflow/.local/lib/python3.6/site-packages/airflow/models/taskinstance.py", line 1137, in _run_raw_task
    self._prepare_and_execute_task_with_callbacks(context, task)
  File "/home/airflow/.local/lib/python3.6/site-packages/airflow/models/taskinstance.py", line 1311, in _prepare_and_execute_task_with_callbacks
    result = self._execute_task(context, task_copy)
  File "/home/airflow/.local/lib/python3.6/site-packages/airflow/models/taskinstance.py", line 1341, in _execute_task
    result = task_copy.execute(context=context)
  File "/home/airflow/.local/lib/python3.6/site-packages/airflow/operators/python.py", line 150, in execute
    return_value = self.execute_callable()
  File "/home/airflow/.local/lib/python3.6/site-packages/airflow/operators/python.py", line 161, in execute_callable
    return self.python_callable(*self.op_args, **self.op_kwargs)
TypeError: __finance() missing 1 required positional argument: 'self'
[2021-06-19 20:30:23,230] {taskinstance.py:1531} INFO - Marking task as FAILED. dag_id=dag_finance, task_id=import_stock_data, execution_date=20210619T203014, start_date=20210619T203022, end_date=20210619T203023
[2021-06-19 20:30:23,299] {local_task_job.py:151} INFO - Task exited with return code 1
